<robot name="robot">

    <link name="base_link">
        <visual>
            <origin xyz="0 0 .033" rpy="0 0 0" />
            <geometry>
                <box size="0.105 0.105 0.066" />
            </geometry>
            <material name="base_link-material">
                <color rgba="1 1 1 1" />
            </material>
        </visual>
        <collision>
            <origin xyz="0 0 .033" rpy="0 0 0" />
            <geometry>
                <box size="0.105 0.105 0.066" />
            </geometry>
        </collision>
        <inertial>
            <origin xyz="0 0 0" rpy="0 0 0" />
            <mass value="0" />
            <inertia ixx="0" ixy="0" ixz="0" iyy="0" iyz="0" izz="0" />
        </inertial>
    </link>

    <joint name="base_link_to_upper_base_link" type="revolute">
        <parent link="base_link" />
        <child link="upper_base_link" />
        <origin xyz="0.000 0 0.10275" rpy="0 0 0" />
        <axis xyz="0 0 -1"/>
        <limit effort="100.0" lower="-3.14159" upper="1.5708" velocity="0.5"/>
    </joint>

    <link name="upper_base_link">
        <visual>
            <origin xyz="0 0 0" rpy="0 0 0" />
            <geometry>
                <cylinder radius="0.05" length="0.0735" />
            </geometry>
            <material name="upper_base_link-material">
                <color rgba="1.0 0.202 0.0 1.0" />
            </material> 
        </visual>
        <collision>
            <origin xyz="0 0 0" rpy="0 0 0" />
            <geometry>
                <cylinder radius="0.05" length="0.0735" />
            </geometry>
        </collision>
        <inertial>
            <origin xyz="0 0 0" rpy="0 0 0" />
            <mass value="0.1" />
            <inertia ixx="0.00333333" ixy="0" ixz="0" iyy="0.005" iyz="0" izz="0.00333333" />
        </inertial>
    </link>

    <joint name="upper_base_link_to_lower_link" type="revolute">
        <parent link="upper_base_link" />
        <child link="lower_link" />
        <origin xyz="0 0 0.02725" rpy="0 0 0" />
        <axis xyz="0 -1 0"/>
        <limit lower="-1.74533" upper="0.95993" effort="30" velocity="1.1"/>
        <!-- <limit lower="-0.95993" upper="1.74533" effort="30" velocity="1.1"/>   -->
    </joint>

    <link name="lower_link">
        <visual>
            <origin xyz="0 0 0.0700" rpy="0 0 0" />
            <geometry>
                <box size="0.025 0.025 0.14" />
            </geometry>
            <material name="lower_link-material">
                <color rgba="0.344 0.328 0.351 1.0" />
            </material>
        </visual>
        <collision>
            <origin xyz="0 0 0.0700" rpy="0 0 0" />
            <geometry>
                <box size="0.025 0.025 0.14" />
            </geometry>
        </collision>
        <inertial>
            <origin xyz="0 0 0.0700" rpy="0 0 0" />
            <mass value="0.1" />
            <inertia ixx="0.00166667" ixy="0" ixz="0" iyy="0.00166667" iyz="0" izz="0.00166667" />
        </inertial>
    </link>

    <link name="virtual_upper_arm_link">
        <visual>
            <geometry>
                <cylinder length="0.01" radius="0.02"/>
            </geometry>
            <material name="virtual_link_material">
                <color rgba="0 0 1 0.5"/>
            </material>
            <origin rpy="0 0 0" xyz="0 0 0"/>
        </visual>
        <collision>
            <geometry>
                <cylinder length="0.01" radius="0.02"/>
            </geometry>
            <origin rpy="0 0 0" xyz="0 0 0"/>
        </collision>
        <inertial>
            <mass value="0.00001"/>
            <inertia ixx="0.00000001" ixy="0.0" ixz="0.0" iyy="0.00000001" iyz="0.0" izz="0.00000001"/>
        </inertial>
    </link>

    <joint name="virtual_upper_arm_joint" type="revolute">
        <parent link="lower_link"/>
        <child link="virtual_upper_arm_link"/>
        <origin xyz="0 0 0.14" rpy="0 0 1.5708"/>
        <axis xyz="1 0 0"/>
        <limit lower="-2.35619" upper="2.35619" effort="20" velocity="1.1"/>
        <mimic joint="upper_base_link_to_lower_link" multiplier="1" offset="0.0"/>
    </joint>

    <joint name="lower_link_to_upper_link" type="revolute">
        <parent link="virtual_upper_arm_link" />
        <child link="upper_link" />
        <origin xyz="0 0 0" rpy="-1.5708 0 3.14159" />
        <axis xyz="1 0 0"/>
        <limit lower="-2.35619" upper="2.35619" effort="20" velocity="1.1"/>
    </joint>

    <link name="upper_link">
        <visual>
            <origin xyz="0 0 0.07" rpy="0 0 0" />
            <geometry>
                <box size="0.025 0.025 0.14" />
            </geometry>
            <material name="upper_link-material">
                <color rgba="0.344 0.328 0.351 1.0" />
            </material>
        </visual>
        <collision>
            <origin xyz="0 0 0.07" rpy="0 0 0" />
            <geometry>
                <box size="0.025 0.025 0.14" />
            </geometry>
        </collision>
        <inertial>
            <origin xyz="0 0 0.07" rpy="0 0 0" />
            <mass value="0.1" />
            <inertia ixx="0.00166667" ixy="0" ixz="0" iyy="0.00166667" iyz="0" izz="0.00166667" />
        </inertial>
    </link>

    <joint name="upper_link_to_end_effector" type="revolute">
        <parent link="upper_link" />
        <child link="end_effector" />
        <origin xyz="0 0 0.1398" rpy="0 0 0" />
        <axis xyz="1 0 0"/>
        <limit lower="-2.35619" upper="2.35619" effort="20" velocity="1.1"/>
        <mimic joint="lower_link_to_upper_link" multiplier="-1" offset="0.0"/>
    </joint>

    <link name="end_effector">
        <visual>
            <origin xyz="0 0 0.03405" rpy="0 0 0" />
            <geometry>
                <box size="0.06 0.016 0.06810" />
            </geometry>
            <material name="end_effector-material">
                <color rgba="1 0 0.065 1" />
            </material>
        </visual>
        <collision>
            <origin xyz="0 0 0.03405" rpy="0 0 0" />
            <geometry>
                <box size="0.06 0.016 0.06810" />
            </geometry>
        </collision>
        <inertial>
            <origin xyz="0 0 0.0155" rpy="0 0 0" />
            <mass value="0.1" />
            <inertia ixx="0.00166667" ixy="0" ixz="0" iyy="0.00166667" iyz="0" izz="0.00166667" />
        </inertial>
    </link>

    <material name="finger_material">
        <color rgba="0.5 0.5 0.5 1.0"/> <!-- Grey color for fingers -->
    </material>

    <link name="left_finger">
        <visual>
            <origin xyz="-0.003 0.015 0.051224" rpy="0 0 0"/>
            <geometry>
                <box size="0.006 0.015 0.02085"/>
            </geometry>
            <color rgba="1 0 0.065 .5" />
        </visual>
        <collision>
            <origin xyz="-0.003 0.015 0.051224" rpy="0 0 0"/>
            <geometry>
                <box size="0.006 0.015 0.02085"/>
            </geometry>
        </collision>
        <inertial>
            <origin xyz="0 0 0" rpy="0 0 0"/>
            <mass value="0.01"/>
            <inertia ixx="1.35e-6" ixy="0" ixz="0" iyy="1.42e-6" iyz="0" izz="1.0e-7"/>
        </inertial>
    </link>

    <link name="right_finger">
        <visual>
            <origin xyz="0.003 0.015 0.051224" rpy="0 0 0"/>
            <geometry>
                <box size="0.006 0.015 0.02085"/>
            </geometry>
            <material name="finger_material"/>
        </visual>
        <collision>
            <origin xyz="0.003 0.015 0.051224" rpy="0 0 0"/>
            <geometry>
                <box size="0.006 0.015 0.02085"/>
            </geometry>
        </collision>
        <inertial>
            <origin xyz="0 0 0" rpy="0 0 0"/>
            <mass value="0.01"/>
            <inertia ixx="1.35e-6" ixy="0" ixz="0" iyy="1.42e-6" iyz="0" izz="1.0e-7"/>
        </inertial>
    </link>
    
    <joint name="left_finger_joint" type="prismatic">
        <parent link="end_effector"/>
        <child link="left_finger"/>
        <origin xyz="0 0 0" rpy="0 0 0"/>
        <axis xyz="-1 0 0"/>
        <limit lower="0.0" upper="0.017" effort="10" velocity="0.05"/>
    </joint>

    <joint name="right_finger_joint" type="prismatic">
        <parent link="end_effector"/>
        <child link="right_finger"/>
        <origin xyz="0 0 0" rpy="0 0 0"/>
        <axis xyz="1 0 0"/>
        <limit lower="0.0" upper="0.017" effort="10" velocity="0.05"/>
        <mimic joint="left_finger_joint" multiplier="1" offset="0.0"/>
    </joint>

    <link name="tcp">
    <visual>
        <origin xyz="0 0 0" rpy="0 0 0"/>
        <geometry>
        <sphere radius="0.005"/> </geometry>
        <material name="red">
        <color rgba="1 0 0 1"/> </material>
    </visual>
    </link>

    <joint name="end_effector_to_tcp" type="fixed">
        <parent link="end_effector"/>  <child link="tcp"/>
        <origin xyz="0 0.015 0.04795" rpy="0 0 0"/>
    </joint>

    <material name="red">
    <color rgba="0 1 0 1"/>
    </material>

</robot>